<?xml version="1.0"?>
<sdf version="1.6">
  <model name="simple_robot">
    
    <!-- Robot body -->
    <link name="base_link">
      <pose>0 0 0.1 0 0 0</pose>
      
      <collision name="base_link_collision">
        <geometry>
          <box><size>0.5 0.4 0.2</size></box>
        </geometry>
      </collision>

      <visual name="visual">
        <geometry>
          <box><size>0.5 0.4 0.2</size></box>
        </geometry>
        <material>
          <ambient>0.3 0.3 0.3 1</ambient>
          <diffuse>0.7 0.7 0.7 1</diffuse>
        </material>
      </visual>

      <inertial>
        <mass>15</mass>
        <inertia>
          <ixx>0.147</ixx>
          <iyy>0.147</iyy>
          <izz>0.147</izz>
        </inertia>
      </inertial>

      <sensor name="bumper" type="contact">
        <contact>
          <collision>base_link_collision</collision>
        </contact>
        <always_on>1</always_on>
        <update_rate>10</update_rate>
        <plugin name="gazebo_ros_bumper" filename="libgazebo_ros_bumper.so">
          <bumperTopicName>/robot/bumper</bumperTopicName>
          <frameName>base_link</frameName>
        </plugin>
      </sensor>
    </link>

    <!-- Left wheel -->
    <link name="left_wheel">
      <pose>0.1 0.25 0.1 1.5707 0 0</pose>
      
      <collision name="collision">
        <geometry>
          <cylinder><radius>0.1</radius><length>0.05</length></cylinder>
        </geometry>
        <surface>
          <friction>
            <ode>
              <mu>100</mu>
              <mu2>50</mu2>
            </ode>
          </friction>
        </surface>
      </collision>

      <visual name="visual">
        <geometry>
          <cylinder><radius>0.1</radius><length>0.05</length></cylinder>
        </geometry>
        <material>
          <ambient>0.1 0.1 0.1 1</ambient>
        </material>
      </visual>

      <inertial>
        <mass>2</mass>
        <inertia>
          <ixx>0.0145</ixx>
          <iyy>0.0145</iyy>
          <izz>0.0145</izz>
        </inertia>
      </inertial>
    </link>

    <!-- Right wheel -->
    <link name="right_wheel">
      <pose>0.1 -0.25 0.1 1.5707 0 0</pose>
      
      <collision name="collision">
        <geometry>
          <cylinder><radius>0.1</radius><length>0.05</length></cylinder>
        </geometry>
        <surface>
          <friction>
            <ode>
              <mu>100</mu>
              <mu2>50</mu2>
            </ode>
          </friction>
        </surface>
      </collision>

      <visual name="visual">
        <geometry>
          <cylinder><radius>0.1</radius><length>0.05</length></cylinder>
        </geometry>
        <material>
          <ambient>0.1 0.1 0.1 1</ambient>
        </material>
      </visual>

      <inertial>
        <mass>2</mass>
        <inertia>
          <ixx>0.0145</ixx>
          <iyy>0.0145</iyy>
          <izz>0.0145</izz>
        </inertia>
      </inertial>
    </link>

    <!-- Caster wheel -->
    <link name="caster">
      <pose>-0.2 0 0.05 0 0 0</pose>
      
      <collision name="collision">
        <geometry>
          <sphere><radius>0.05</radius></sphere>
        </geometry>
        <surface>
          <friction>
            <ode>
              <mu>0</mu>
              <mu2>0</mu2>
              <slip1>1.0</slip1>
              <slip2>1.0</slip2>
            </ode>
          </friction>
        </surface>
      </collision>

      <visual name="visual">
        <geometry>
          <sphere><radius>0.05</radius></sphere>
        </geometry>
      </visual>

      <inertial>
        <mass>0.5</mass>
        <inertia>
          <ixx>0.001</ixx>
          <iyy>0.001</iyy>
          <izz>0.001</izz>
        </inertia>
      </inertial>
    </link>

    <!-- Joints -->
    <joint name="left_wheel_joint" type="revolute">
      <parent>base_link</parent>
      <child>left_wheel</child>
      <axis>
        <xyz>0 0 1</xyz>
      </axis>
    </joint>

    <joint name="right_wheel_joint" type="revolute">
      <parent>base_link</parent>
      <child>right_wheel</child>
      <axis>
        <xyz>0 0 1</xyz>
      </axis>
    </joint>

    <joint name="caster_joint" type="fixed">
      <parent>base_link</parent>
      <child>caster</child>
    </joint>

    <!-- LIDAR -->
    <link name="lidar_link">
      <pose>0.2 0 0.25 0 0 0</pose>
      
      <visual name="visual">
        <geometry>
          <cylinder><radius>0.05</radius><length>0.07</length></cylinder>
        </geometry>
      </visual>

      <sensor name="lidar" type="ray">
        <pose>0 0 0 0 0 0</pose>
        <ray>
          <scan>
            <horizontal>
              <samples>360</samples>
              <resolution>1</resolution>
              <min_angle>-3.14159</min_angle>
              <max_angle>3.14159</max_angle>
            </horizontal>
          </scan>
          <range>
            <min>0.1</min>
            <max>10.0</max>
            <resolution>0.01</resolution>
          </range>
        </ray>
        <always_on>1</always_on>
        <update_rate>10</update_rate>
        <visualize>false</visualize>
        
        <plugin name="gazebo_ros_lidar" filename="libgazebo_ros_laser.so">
          <topicName>/robot/laser/scan</topicName>
          <frameName>lidar_link</frameName>
        </plugin>
      </sensor>

      <inertial>
        <mass>0.1</mass>
        <inertia>
          <ixx>0.001</ixx>
          <iyy>0.001</iyy>
          <izz>0.001</izz>
        </inertia>
      </inertial>
    </link>

    <joint name="lidar_joint" type="fixed">
      <parent>base_link</parent>
      <child>lidar_link</child>
    </joint>

    <!-- Differential Drive Plugin -->
    <plugin name="differential_drive_controller" filename="libgazebo_ros_diff_drive.so">
      <rosDebugLevel>na</rosDebugLevel>
      <publishWheelTF>false</publishWheelTF>
      <robotNamespace>/</robotNamespace>
      <publishTf>1</publishTf>
      <publishWheelJointState>false</publishWheelJointState>
      <alwaysOn>true</alwaysOn>
      <updateRate>100.0</updateRate>
      <legacyMode>true</legacyMode>
      <leftJoint>left_wheel_joint</leftJoint>
      <rightJoint>right_wheel_joint</rightJoint>
      <wheelSeparation>0.5</wheelSeparation>
      <wheelDiameter>0.2</wheelDiameter>
      <broadcastTF>1</broadcastTF>
      <wheelTorque>20</wheelTorque>
      <wheelAcceleration>1.8</wheelAcceleration>
      <commandTopic>cmd_vel</commandTopic>
      <odometryFrame>odom</odometryFrame>
      <odometryTopic>odom</odometryTopic>
      <robotBaseFrame>base_link</robotBaseFrame>
    </plugin>

    <!-- Ground Truth Plugin -->
    <plugin name="ground_truth" filename="libgazebo_ros_p3d.so">
      <alwaysOn>true</alwaysOn>
      <updateRate>100.0</updateRate>
      <bodyName>base_link</bodyName>
      <topicName>/robot/ground_truth/state</topicName>
      <frameName>world</frameName>
      <xyzOffsets>0 0 0</xyzOffsets>
      <rpyOffsets>0 0 0</rpyOffsets>
    </plugin>

  </model>
</sdf>
