<?xml version="1.0"?>
<sdf version="1.6">
  <model name="simple_robot">
    
    <!-- Robot body (main chassis) -->
    <link name="base_link">
      <pose>0 0 0.1 0 0 0</pose>
      
      <collision name="base_link_collision">
        <geometry>
          <box><size>0.5 0.4 0.2</size></box>
        </geometry>
      </collision>

      <visual name="visual">
        <geometry>
          <box><size>0.5 0.4 0.2</size></box>
        </geometry>
        <material>
          <ambient>0.3 0.3 0.3 1</ambient>
          <diffuse>0.7 0.7 0.7 1</diffuse>
        </material>
      </visual>

      <inertial>
        <mass>15</mass>
        <inertia>
          <ixx>0.147</ixx>
          <iyy>0.147</iyy>
          <izz>0.147</izz>
        </inertia>
      </inertial>

      <!-- CONTACT SENSOR (now properly linked to collision) -->
      <sensor name="bumper" type="contact">
        <contact>
          <collision>base_link_collision</collision>
        </contact>
        <always_on>1</always_on>
        <update_rate>10</update_rate>
        <plugin name="gazebo_ros_bumper" filename="libgazebo_ros_bumper.so">
          <bumperTopicName>/robot/bumper</bumperTopicName>
          <frameName>base_link</frameName>
        </plugin>
      </sensor>
    </link>

    <!-- Left wheel -->
    <link name="left_wheel">
      <pose>0.1 0.25 0.1 1.5707 0 0</pose>
      
      <collision name="collision">
        <geometry>
          <cylinder><radius>0.1</radius><length>0.05</length></cylinder>
        </geometry>
        <surface>
          <friction>
            <ode>
              <mu>100</mu>
              <mu2>50</mu2>
            </ode>
          </friction>
        </surface>
      </collision>

      <visual name="visual">
        <geometry>
          <cylinder><radius>0.1</radius><length>0.05</length></cylinder>
        </geometry>
        <material>
          <ambient>0.1 0.1 0.1 1</ambient>
          <diffuse>0.2 0.2 0.2 1</diffuse>
        </material>
      </visual>

      <inertial>
        <mass>2</mass>
        <inertia>
          <ixx>0.0145</ixx>
          <iyy>0.0145</iyy>
          <izz>0.0145</izz>
        </inertia>
      </inertial>
    </link>

    <!-- Right wheel -->
    <link name="right_wheel">
      <pose>0.1 -0.25 0.1 1.5707 0 0</pose>
      
      <collision name="collision">
        <geometry>
          <cylinder><radius>0.1</radius><length>0.05</length></cylinder>
        </geometry>
        <surface>
          <friction>
            <ode>
              <mu>100</mu>
              <mu2>50</mu2>
            </ode>
          </friction>
        </surface>
      </collision>

      <visual name="visual">
        <geometry>
          <cylinder><radius>0.1</radius><length>0.05</length></cylinder>
        </geometry>
        <material>
          <ambient>0.1 0.1 0.1 1</ambient>
          <diffuse>0.2 0.2 0.2 1</diffuse>
        </material>
      </visual>

      <inertial>
        <mass>2</mass>
        <inertia>
          <ixx>0.0145</ixx>
          <iyy>0.0145</iyy>
          <izz>0.0145</izz>
        </inertia>
      </inertial>
    </link>

    <!-- Caster wheel (for stability) -->
    <link name="caster">
      <pose>-0.2 0 0.05 0 0 0</pose>
      
      <collision name="collision">
        <geometry>
          <sphere><radius>0.05</radius></sphere>
        </geometry>
        <surface>
          <friction>
            <ode>
              <mu>0</mu>
              <mu2>0</mu2>
              <slip1>1.0</slip1>
              <slip2>1.0</slip2>
            </ode>
          </friction>
        </surface>
      </collision>

      <visual name="visual">
        <geometry>
          <sphere><radius>0.05</radius></sphere>
        </geometry>
        <material>
          <ambient>0.3 0.3 0.3 1</ambient>
        </material>
      </visual>

      <inertial>
        <mass>0.5</mass>
        <inertia>
          <ixx>0.001</ixx>
          <iyy>0.001</iyy>
          <izz>0.001</izz>
        </inertia>
      </inertial>
    </link>

    <!-- Left wheel joint -->
    <joint name="left_wheel_joint" type="revolute">
      <parent>base_link</parent>
      <child>left_wheel</child>
      <axis>
        <xyz>0 0 1</xyz>
        <limit>
          <lower>-1e16</lower>
          <upper>1e16</upper>
        </limit>
      </axis>
    </joint>

    <!-- Right wheel joint -->
    <joint name="right_wheel_joint" type="revolute">
      <parent>base_link</parent>
      <child>right_wheel</child>
      <axis>
        <xyz>0 0 1</xyz>
        <limit>
          <lower>-1e16</lower>
          <upper>1e16</upper>
        </limit>
      </axis>
    </joint>

    <!-- Caster joint -->
    <joint name="caster_joint" type="fixed">
      <parent>base_link</parent>
      <child>caster</child>
    </joint>

    <!-- LIDAR/Laser Scanner -->
    <link name="lidar_link">
      <pose>0.2 0 0.25 0 0 0</pose>
      
      <visual name="visual">
        <geometry>
          <cylinder><radius>0.05</radius><length>0.07</length></cylinder>
        </geometry>
        <material>
          <ambient>0 0 0 1</ambient>
          <diffuse>0.1 0.1 0.1 1</diffuse>
        </material>
      </visual>

      <sensor name="lidar" type="ray">
        <pose>0 0 0 0 0 0</pose>
        <ray>
          <scan>
            <horizontal>
              <samples>360</samples>
              <resolution>1</resolution>
              <min_angle>-3.14159</min_angle>
              <max_angle>3.14159</max_angle>
            </horizontal>
          </scan>
          <range>
            <min>0.1</min>
            <max>10.0</max>
            <resolution>0.01</resolution>
          </range>
        </ray>
        <always_on>1</always_on>
        <update_rate>10</update_rate>
        <visualize>true</visualize>
        
        <!-- ROS PLUGIN FOR LIDAR -->
        <plugin name="gazebo_ros_lidar" filename="libgazebo_ros_laser.so">
          <topicName>/robot/laser/scan</topicName>
          <frameName>lidar_link</frameName>
        </plugin>
      </sensor>

      <inertial>
        <mass>0.1</mass>
        <inertia>
          <ixx>0.001</ixx>
          <iyy>0.001</iyy>
          <izz>0.001</izz>
        </inertia>
      </inertial>
    </link>

    <joint name="lidar_joint" type="fixed">
      <parent>base_link</parent>
      <child>lidar_link</child>
    </joint>

    <!-- Camera -->
    <link name="camera_link">
      <pose>0.25 0 0.15 0 0 0</pose>
      
      <visual name="visual">
        <geometry>
          <box><size>0.05 0.1 0.05</size></box>
        </geometry>
        <material>
          <ambient>0 0 1 1</ambient>
          <diffuse>0.2 0.2 0.8 1</diffuse>
        </material>
      </visual>

      <sensor name="camera" type="camera">
        <camera>
          <horizontal_fov>1.047</horizontal_fov>
          <image>
            <width>640</width>
            <height>480</height>
            <format>R8G8B8</format>
          </image>
          <clip>
            <near>0.1</near>
            <far>100</far>
          </clip>
        </camera>
        <always_on>1</always_on>
        <update_rate>30</update_rate>
        <visualize>true</visualize>
        
        <!-- ROS PLUGIN FOR CAMERA -->
        <plugin name="gazebo_ros_camera" filename="libgazebo_ros_camera.so">
          <cameraName>robot/camera</cameraName>
          <imageTopicName>image_raw</imageTopicName>
          <cameraInfoTopicName>camera_info</cameraInfoTopicName>
          <frameName>camera_link</frameName>
        </plugin>
      </sensor>

      <inertial>
        <mass>0.1</mass>
        <inertia>
          <ixx>0.001</ixx>
          <iyy>0.001</iyy>
          <izz>0.001</izz>
        </inertia>
      </inertial>
    </link>

    <joint name="camera_joint" type="fixed">
      <parent>base_link</parent>
      <child>camera_link</child>
    </joint>

    <!-- IMU sensor -->
    <link name="imu_link">
      <pose>0 0 0.15 0 0 0</pose>
      
      <sensor name="imu" type="imu">
        <always_on>1</always_on>
        <update_rate>100</update_rate>
        <imu>
          <angular_velocity>
            <x>
              <noise type="gaussian">
                <mean>0.0</mean>
                <stddev>2e-4</stddev>
              </noise>
            </x>
            <y>
              <noise type="gaussian">
                <mean>0.0</mean>
                <stddev>2e-4</stddev>
              </noise>
            </y>
            <z>
              <noise type="gaussian">
                <mean>0.0</mean>
                <stddev>2e-4</stddev>
              </noise>
            </z>
          </angular_velocity>
          <linear_acceleration>
            <x>
              <noise type="gaussian">
                <mean>0.0</mean>
                <stddev>1.7e-2</stddev>
              </noise>
            </x>
            <y>
              <noise type="gaussian">
                <mean>0.0</mean>
                <stddev>1.7e-2</stddev>
              </noise>
            </y>
            <z>
              <noise type="gaussian">
                <mean>0.0</mean>
                <stddev>1.7e-2</stddev>
              </noise>
            </z>
          </linear_acceleration>
        </imu>
        
        <!-- ROS PLUGIN FOR IMU -->
        <plugin name="gazebo_ros_imu" filename="libgazebo_ros_imu.so">
          <topicName>/robot/imu</topicName>
          <bodyName>imu_link</bodyName>
          <frameName>imu_link</frameName>
          <updateRateHZ>100</updateRateHZ>
          <gaussianNoise>0.01</gaussianNoise>
        </plugin>
      </sensor>

      <inertial>
        <mass>0.01</mass>
        <inertia>
          <ixx>0.0001</ixx>
          <iyy>0.0001</iyy>
          <izz>0.0001</izz>
        </inertia>
      </inertial>
    </link>

    <joint name="imu_joint" type="fixed">
      <parent>base_link</parent>
      <child>imu_link</child>
    </joint>

    <!-- DIFFERENTIAL DRIVE PLUGIN - CRITICAL FOR CONTROL! -->
    <plugin name="differential_drive_controller" filename="libgazebo_ros_diff_drive.so">
      <rosDebugLevel>Debug</rosDebugLevel>
      <publishWheelTF>true</publishWheelTF>
      <robotNamespace>/</robotNamespace>
      <publishTf>1</publishTf>
      <publishWheelJointState>true</publishWheelJointState>
      <alwaysOn>true</alwaysOn>
      <updateRate>100.0</updateRate>
      <legacyMode>true</legacyMode>
      <leftJoint>left_wheel_joint</leftJoint>
      <rightJoint>right_wheel_joint</rightJoint>
      <wheelSeparation>0.5</wheelSeparation>
      <wheelDiameter>0.2</wheelDiameter>
      <broadcastTF>1</broadcastTF>
      <wheelTorque>20</wheelTorque>
      <wheelAcceleration>1.8</wheelAcceleration>
      <commandTopic>cmd_vel</commandTopic>
      <odometryFrame>odom</odometryFrame>
      <odometryTopic>odom</odometryTopic>
      <robotBaseFrame>base_link</robotBaseFrame>
    </plugin>

    <!-- GROUND TRUTH ODOMETRY PLUGIN (useful for RL training) -->
    <plugin name="ground_truth" filename="libgazebo_ros_p3d.so">
      <alwaysOn>true</alwaysOn>
      <updateRate>100.0</updateRate>
      <bodyName>base_link</bodyName>
      <topicName>/robot/ground_truth/state</topicName>
      <frameName>world</frameName>
      <xyzOffsets>0 0 0</xyzOffsets>
      <rpyOffsets>0 0 0</rpyOffsets>
    </plugin>

  </model>
</sdf>